<?xml version="1.0" ?>
<!-- =================================================================================== -->
<!-- |    This document was autogenerated by xacro from /home/shivu/argo_mini_ws/src/argo_mini/urdf/argo_mini.xacro | -->
<!-- |    EDITING THIS FILE BY HAND IS NOT RECOMMENDED                                 | -->
<!-- =================================================================================== -->
<robot name="robot_chassis">
  <material name="aluminum">
    <color rgba="0.85 0.85 0.88 1.0"/>
  </material>
  <material name="black">
    <color rgba="0.05 0.05 0.05 1.0"/>
  </material>
  <material name="dark_grey">
    <color rgba="0.30 0.30 0.30 1.0"/>
  </material>
  <material name="silver">
    <color rgba="0.70 0.70 0.72 1.0"/>
  </material>
  <link name="base_footprint"/>
  <link name="base_link">
    <visual>
      <origin rpy="0 0 0" xyz="0.20500000000000002 0 0.0015"/>
      <geometry>
        <box size="0.10999999999999999 0.435 0.003"/>
      </geometry>
      <material name="aluminum"/>
    </visual>
    <collision>
      <origin rpy="0 0 0" xyz="0.20500000000000002 0 0.0015"/>
      <geometry>
        <box size="0.10999999999999999 0.435 0.003"/>
      </geometry>
    </collision>
    <visual>
      <origin rpy="0 0 0" xyz="-0.15 0 0.0015"/>
      <geometry>
        <box size="0.22000000000000003 0.435 0.003"/>
      </geometry>
      <material name="aluminum"/>
    </visual>
    <collision>
      <origin rpy="0 0 0" xyz="-0.15 0 0.0015"/>
      <geometry>
        <box size="0.22000000000000003 0.435 0.003"/>
      </geometry>
    </collision>
    <visual>
      <origin rpy="0 0 0" xyz="0.05500000000000002 0 0.0015"/>
      <geometry>
        <box size="0.19 0.34500000000000003 0.003"/>
      </geometry>
      <material name="aluminum"/>
    </visual>
    <collision>
      <origin rpy="0 0 0" xyz="0.05500000000000002 0 0.0015"/>
      <geometry>
        <box size="0.19 0.34500000000000003 0.003"/>
      </geometry>
    </collision>
    <inertial>
      <mass value="2.0"/>
      <origin rpy="0 0 0" xyz="0 0 0"/>
      <inertia ixx="0.031539000000000005" ixy="0" ixz="0" iyy="0.045068166666666666" iyz="0" izz="0.07660416666666668"/>
    </inertial>
  </link>
  <joint name="base_footprint_to_base_link" type="fixed">
    <parent link="base_footprint"/>
    <child link="base_link"/>
    <origin rpy="0 0 0" xyz="0 0 0.06"/>
  </joint>
  <link name="upper_plate_link">
    <visual>
      <origin rpy="0 0 0" xyz="-0.15 0 0.0015"/>
      <geometry>
        <box size="0.22000000000000003 0.435 0.003"/>
      </geometry>
      <material name="aluminum"/>
    </visual>
    <collision>
      <origin rpy="0 0 0" xyz="-0.15 0 0.0015"/>
      <geometry>
        <box size="0.22000000000000003 0.435 0.003"/>
      </geometry>
    </collision>
    <visual>
      <origin rpy="0 0 0" xyz="0.023750000000000014 0 0.0015"/>
      <geometry>
        <box size="0.1275 0.34500000000000003 0.003"/>
      </geometry>
      <material name="aluminum"/>
    </visual>
    <collision>
      <origin rpy="0 0 0" xyz="0.023750000000000014 0 0.0015"/>
      <geometry>
        <box size="0.1275 0.34500000000000003 0.003"/>
      </geometry>
    </collision>
    <visual>
      <origin rpy="0 0 0" xyz="0.11875000000000002 0.11125000000000002 0.0015"/>
      <geometry>
        <box size="0.06250000000000001 0.12250000000000001 0.003"/>
      </geometry>
      <material name="aluminum"/>
    </visual>
    <collision>
      <origin rpy="0 0 0" xyz="0.11875000000000002 0.11125000000000002 0.0015"/>
      <geometry>
        <box size="0.06250000000000001 0.12250000000000001 0.003"/>
      </geometry>
    </collision>
    <visual>
      <origin rpy="0 0 0" xyz="0.11875000000000002 -0.11125000000000002 0.0015"/>
      <geometry>
        <box size="0.06250000000000001 0.12250000000000001 0.003"/>
      </geometry>
      <material name="aluminum"/>
    </visual>
    <collision>
      <origin rpy="0 0 0" xyz="0.11875000000000002 -0.11125000000000002 0.0015"/>
      <geometry>
        <box size="0.06250000000000001 0.12250000000000001 0.003"/>
      </geometry>
    </collision>
    <visual>
      <origin rpy="0 0 0" xyz="0.16875 0.13375 0.0015"/>
      <geometry>
        <box size="0.03749999999999998 0.16749999999999998 0.003"/>
      </geometry>
      <material name="aluminum"/>
    </visual>
    <collision>
      <origin rpy="0 0 0" xyz="0.16875 0.13375 0.0015"/>
      <geometry>
        <box size="0.03749999999999998 0.16749999999999998 0.003"/>
      </geometry>
    </collision>
    <visual>
      <origin rpy="0 0 0" xyz="0.16875 -0.13375 0.0015"/>
      <geometry>
        <box size="0.03749999999999998 0.16749999999999998 0.003"/>
      </geometry>
      <material name="aluminum"/>
    </visual>
    <collision>
      <origin rpy="0 0 0" xyz="0.16875 -0.13375 0.0015"/>
      <geometry>
        <box size="0.03749999999999998 0.16749999999999998 0.003"/>
      </geometry>
    </collision>
    <visual>
      <origin rpy="0 0 0" xyz="0.22375 0 0.0015"/>
      <geometry>
        <box size="0.07250000000000001 0.435 0.003"/>
      </geometry>
      <material name="aluminum"/>
    </visual>
    <collision>
      <origin rpy="0 0 0" xyz="0.22375 0 0.0015"/>
      <geometry>
        <box size="0.07250000000000001 0.435 0.003"/>
      </geometry>
    </collision>
    <inertial>
      <mass value="2.0"/>
      <origin rpy="0 0 0" xyz="0 0 0"/>
      <inertia ixx="0.031539000000000005" ixy="0" ixz="0" iyy="0.045068166666666666" iyz="0" izz="0.07660416666666668"/>
    </inertial>
  </link>
  <joint name="lower_plate_to_upper_plate" type="fixed">
    <parent link="base_link"/>
    <child link="upper_plate_link"/>
    <origin rpy="0 0 0" xyz="0 0 0.11"/>
  </joint>
  <link name="standoff_fl_link">
    <visual>
      <origin rpy="0 0 0" xyz="0 0 0.08"/>
      <geometry>
        <box size="0.025 0.025 0.16"/>
      </geometry>
      <material name="silver"/>
    </visual>
    <collision>
      <origin rpy="0 0 0" xyz="0 0 0.08"/>
      <geometry>
        <box size="0.025 0.025 0.16"/>
      </geometry>
    </collision>
    <inertial>
      <mass value="0.05"/>
      <origin rpy="0 0 0" xyz="0 0 0"/>
      <inertia ixx="0.00010927083333333334" ixy="0" ixz="0" iyy="0.00010927083333333334" iyz="0" izz="5.208333333333335e-06"/>
    </inertial>
  </link>
  <joint name="standoff_fl_joint" type="fixed">
    <parent link="base_link"/>
    <child link="standoff_fl_link"/>
    <origin rpy="0 0 0" xyz="0.22 0.1925 0.003"/>
  </joint>
  <link name="standoff_fr_link">
    <visual>
      <origin rpy="0 0 0" xyz="0 0 0.08"/>
      <geometry>
        <box size="0.025 0.025 0.16"/>
      </geometry>
      <material name="silver"/>
    </visual>
    <collision>
      <origin rpy="0 0 0" xyz="0 0 0.08"/>
      <geometry>
        <box size="0.025 0.025 0.16"/>
      </geometry>
    </collision>
    <inertial>
      <mass value="0.05"/>
      <origin rpy="0 0 0" xyz="0 0 0"/>
      <inertia ixx="0.00010927083333333334" ixy="0" ixz="0" iyy="0.00010927083333333334" iyz="0" izz="5.208333333333335e-06"/>
    </inertial>
  </link>
  <joint name="standoff_fr_joint" type="fixed">
    <parent link="base_link"/>
    <child link="standoff_fr_link"/>
    <origin rpy="0 0 0" xyz="0.22 -0.1925 0.003"/>
  </joint>
  <link name="standoff_rl_link">
    <visual>
      <origin rpy="0 0 0" xyz="0 0 0.08"/>
      <geometry>
        <box size="0.025 0.025 0.16"/>
      </geometry>
      <material name="silver"/>
    </visual>
    <collision>
      <origin rpy="0 0 0" xyz="0 0 0.08"/>
      <geometry>
        <box size="0.025 0.025 0.16"/>
      </geometry>
    </collision>
    <inertial>
      <mass value="0.05"/>
      <origin rpy="0 0 0" xyz="0 0 0"/>
      <inertia ixx="0.00010927083333333334" ixy="0" ixz="0" iyy="0.00010927083333333334" iyz="0" izz="5.208333333333335e-06"/>
    </inertial>
  </link>
  <joint name="standoff_rl_joint" type="fixed">
    <parent link="base_link"/>
    <child link="standoff_rl_link"/>
    <origin rpy="0 0 0" xyz="-0.07999999999999999 0.135 0.003"/>
  </joint>
  <link name="standoff_rr_link">
    <visual>
      <origin rpy="0 0 0" xyz="0 0 0.08"/>
      <geometry>
        <box size="0.025 0.025 0.16"/>
      </geometry>
      <material name="silver"/>
    </visual>
    <collision>
      <origin rpy="0 0 0" xyz="0 0 0.08"/>
      <geometry>
        <box size="0.025 0.025 0.16"/>
      </geometry>
    </collision>
    <inertial>
      <mass value="0.05"/>
      <origin rpy="0 0 0" xyz="0 0 0"/>
      <inertia ixx="0.00010927083333333334" ixy="0" ixz="0" iyy="0.00010927083333333334" iyz="0" izz="5.208333333333335e-06"/>
    </inertial>
  </link>
  <joint name="standoff_rr_joint" type="fixed">
    <parent link="base_link"/>
    <child link="standoff_rr_link"/>
    <origin rpy="0 0 0" xyz="-0.07999999999999999 -0.135 0.003"/>
  </joint>
  <link name="left_wheel_link">
    <visual>
      <origin rpy="1.5707963267948966 0 0" xyz="0 0 0"/>
      <geometry>
        <cylinder length="0.05" radius="0.085"/>
      </geometry>
      <material name="black"/>
    </visual>
    <collision>
      <origin rpy="1.5707963267948966 0 0" xyz="0 0 0"/>
      <geometry>
        <cylinder length="0.05" radius="0.085"/>
      </geometry>
    </collision>
    <inertial>
      <mass value="1.5"/>
      <origin rpy="0 0 0" xyz="0 0 0"/>
      <inertia ixx="0.0030218750000000003" ixy="0" ixz="0" iyy="0.0030218750000000003" iyz="0" izz="0.005418750000000001"/>
    </inertial>
  </link>
  <joint name="left_wheel_joint" type="continuous">
    <parent link="base_link"/>
    <child link="left_wheel_link"/>
    <origin rpy="0 0 0" xyz="0.05500000000000002 0.1975 0.02500000000000001"/>
    <axis xyz="0 1 0"/>
    <limit effort="10.0" velocity="10.0"/>
    <dynamics damping="0.1" friction="0.1"/>
  </joint>
  <link name="right_wheel_link">
    <visual>
      <origin rpy="1.5707963267948966 0 0" xyz="0 0 0"/>
      <geometry>
        <cylinder length="0.05" radius="0.085"/>
      </geometry>
      <material name="black"/>
    </visual>
    <collision>
      <origin rpy="1.5707963267948966 0 0" xyz="0 0 0"/>
      <geometry>
        <cylinder length="0.05" radius="0.085"/>
      </geometry>
    </collision>
    <inertial>
      <mass value="1.5"/>
      <origin rpy="0 0 0" xyz="0 0 0"/>
      <inertia ixx="0.0030218750000000003" ixy="0" ixz="0" iyy="0.0030218750000000003" iyz="0" izz="0.005418750000000001"/>
    </inertial>
  </link>
  <joint name="right_wheel_joint" type="continuous">
    <parent link="base_link"/>
    <child link="right_wheel_link"/>
    <origin rpy="0 0 0" xyz="0.05500000000000002 -0.1975 0.02500000000000001"/>
    <axis xyz="0 1 0"/>
    <limit effort="10.0" velocity="10.0"/>
    <dynamics damping="0.1" friction="0.1"/>
  </joint>
  <link name="caster_mount_rl_link">
    <visual>
      <origin rpy="0 0 0" xyz="0 0 -0.0025"/>
      <geometry>
        <cylinder length="0.005" radius="0.018"/>
      </geometry>
      <material name="silver"/>
    </visual>
    <collision>
      <origin rpy="0 0 0" xyz="0 0 -0.0025"/>
      <geometry>
        <cylinder length="0.005" radius="0.018"/>
      </geometry>
    </collision>
    <inertial>
      <mass value="0.02"/>
      <origin rpy="0 0 0" xyz="0 0 0"/>
      <inertia ixx="1.6616666666666665e-06" ixy="0" ixz="0" iyy="1.6616666666666665e-06" iyz="0" izz="3.2399999999999995e-06"/>
    </inertial>
  </link>
  <joint name="caster_mount_rl_joint" type="fixed">
    <parent link="base_link"/>
    <child link="caster_mount_rl_link"/>
    <origin rpy="0 0 0" xyz="-0.16 0.135 0"/>
  </joint>
  <link name="caster_yaw_rl_link">
    <visual>
      <origin rpy="0 0 0" xyz="-0.006 0 -0.0125"/>
      <geometry>
        <box size="0.022 0.012 0.025"/>
      </geometry>
      <material name="silver"/>
    </visual>
    <collision>
      <origin rpy="0 0 0" xyz="-0.006 0 -0.0125"/>
      <geometry>
        <box size="0.022 0.012 0.025"/>
      </geometry>
    </collision>
    <inertial>
      <mass value="0.03"/>
      <origin rpy="0 0 0" xyz="0 0 0"/>
      <inertia ixx="1.9225000000000002e-06" ixy="0" ixz="0" iyy="2.7725000000000006e-06" iyz="0" izz="1.57e-06"/>
    </inertial>
  </link>
  <joint name="caster_yaw_rl_joint" type="continuous">
    <parent link="caster_mount_rl_link"/>
    <child link="caster_yaw_rl_link"/>
    <origin rpy="0 0 0" xyz="0 0 -0.005"/>
    <axis xyz="0 0 1"/>
    <dynamics damping="0.02" friction="0.005"/>
  </joint>
  <link name="caster_wheel_rl_link">
    <visual>
      <origin rpy="1.5707963267948966 0 0" xyz="0 0 0"/>
      <geometry>
        <cylinder length="0.02" radius="0.03"/>
      </geometry>
      <material name="dark_grey"/>
    </visual>
    <collision>
      <origin rpy="1.5707963267948966 0 0" xyz="0 0 0"/>
      <geometry>
        <cylinder length="0.02" radius="0.03"/>
      </geometry>
    </collision>
    <inertial>
      <mass value="0.08"/>
      <origin rpy="0 0 0" xyz="0 0 0"/>
      <inertia ixx="2.0666666666666666e-05" ixy="0" ixz="0" iyy="2.0666666666666666e-05" iyz="0" izz="3.5999999999999994e-05"/>
    </inertial>
  </link>
  <joint name="caster_wheel_rl_joint" type="continuous">
    <parent link="caster_yaw_rl_link"/>
    <child link="caster_wheel_rl_link"/>
    <origin rpy="0 0 0" xyz="-0.012 0 -0.025"/>
    <axis xyz="0 1 0"/>
    <dynamics damping="0.05" friction="0.01"/>
  </joint>
  <link name="caster_mount_rr_link">
    <visual>
      <origin rpy="0 0 0" xyz="0 0 -0.0025"/>
      <geometry>
        <cylinder length="0.005" radius="0.018"/>
      </geometry>
      <material name="silver"/>
    </visual>
    <collision>
      <origin rpy="0 0 0" xyz="0 0 -0.0025"/>
      <geometry>
        <cylinder length="0.005" radius="0.018"/>
      </geometry>
    </collision>
    <inertial>
      <mass value="0.02"/>
      <origin rpy="0 0 0" xyz="0 0 0"/>
      <inertia ixx="1.6616666666666665e-06" ixy="0" ixz="0" iyy="1.6616666666666665e-06" iyz="0" izz="3.2399999999999995e-06"/>
    </inertial>
  </link>
  <joint name="caster_mount_rr_joint" type="fixed">
    <parent link="base_link"/>
    <child link="caster_mount_rr_link"/>
    <origin rpy="0 0 0" xyz="-0.16 -0.135 0"/>
  </joint>
  <link name="caster_yaw_rr_link">
    <visual>
      <origin rpy="0 0 0" xyz="-0.006 0 -0.0125"/>
      <geometry>
        <box size="0.022 0.012 0.025"/>
      </geometry>
      <material name="silver"/>
    </visual>
    <collision>
      <origin rpy="0 0 0" xyz="-0.006 0 -0.0125"/>
      <geometry>
        <box size="0.022 0.012 0.025"/>
      </geometry>
    </collision>
    <inertial>
      <mass value="0.03"/>
      <origin rpy="0 0 0" xyz="0 0 0"/>
      <inertia ixx="1.9225000000000002e-06" ixy="0" ixz="0" iyy="2.7725000000000006e-06" iyz="0" izz="1.57e-06"/>
    </inertial>
  </link>
  <joint name="caster_yaw_rr_joint" type="continuous">
    <parent link="caster_mount_rr_link"/>
    <child link="caster_yaw_rr_link"/>
    <origin rpy="0 0 0" xyz="0 0 -0.005"/>
    <axis xyz="0 0 1"/>
    <dynamics damping="0.02" friction="0.005"/>
  </joint>
  <link name="caster_wheel_rr_link">
    <visual>
      <origin rpy="1.5707963267948966 0 0" xyz="0 0 0"/>
      <geometry>
        <cylinder length="0.02" radius="0.03"/>
      </geometry>
      <material name="dark_grey"/>
    </visual>
    <collision>
      <origin rpy="1.5707963267948966 0 0" xyz="0 0 0"/>
      <geometry>
        <cylinder length="0.02" radius="0.03"/>
      </geometry>
    </collision>
    <inertial>
      <mass value="0.08"/>
      <origin rpy="0 0 0" xyz="0 0 0"/>
      <inertia ixx="2.0666666666666666e-05" ixy="0" ixz="0" iyy="2.0666666666666666e-05" iyz="0" izz="3.5999999999999994e-05"/>
    </inertial>
  </link>
  <joint name="caster_wheel_rr_joint" type="continuous">
    <parent link="caster_yaw_rr_link"/>
    <child link="caster_wheel_rr_link"/>
    <origin rpy="0 0 0" xyz="-0.012 0 -0.025"/>
    <axis xyz="0 1 0"/>
    <dynamics damping="0.05" friction="0.01"/>
  </joint>
  <link name="lidar_link">
    <visual>
      <origin rpy="0 0 0" xyz="0 0 0"/>
      <geometry>
        <cylinder length="0.041" radius="0.038"/>
      </geometry>
      <material name="black"/>
    </visual>
    <collision>
      <origin rpy="0 0 0" xyz="0 0 0"/>
      <geometry>
        <cylinder length="0.041" radius="0.038"/>
      </geometry>
    </collision>
    <inertial>
      <mass value="0.19"/>
      <origin rpy="0 0 0" xyz="0 0 0"/>
      <inertia ixx="9.520583333333334e-05" ixy="0" ixz="0" iyy="9.520583333333334e-05" iyz="0" izz="0.00013717999999999998"/>
    </inertial>
  </link>
  <joint name="lidar_joint" type="fixed">
    <parent link="base_link"/>
    <child link="lidar_link"/>
    <origin rpy="0 0 0" xyz="0.1375 0 0.1095"/>
  </joint>
  <link name="camera_link">
    <visual>
      <origin rpy="0 0 0" xyz="0 0 0"/>
      <geometry>
        <box size="0.025 0.09 0.025"/>
      </geometry>
      <material name="dark_grey"/>
    </visual>
    <collision>
      <origin rpy="0 0 0" xyz="0 0 0"/>
      <geometry>
        <box size="0.025 0.09 0.025"/>
      </geometry>
    </collision>
    <inertial>
      <mass value="0.1"/>
      <origin rpy="0 0 0" xyz="0 0 0"/>
      <inertia ixx="7.270833333333333e-05" ixy="0" ixz="0" iyy="1.041666666666667e-05" iyz="0" izz="7.270833333333333e-05"/>
    </inertial>
  </link>
  <joint name="camera_joint" type="fixed">
    <parent link="base_link"/>
    <child link="camera_link"/>
    <origin rpy="0 0 0" xyz="0.2575 0 0.170"/>
  </joint>
  <link name="depth_camera_optical_frame"/>
  <joint name="camera_optical_joint" type="fixed">
    <parent link="camera_link"/>
    <child link="depth_camera_optical_frame"/>
    <origin rpy="-1.5707963267948966 0 -1.5707963267948966" xyz="0 0 0"/>
  </joint>
  <gazebo reference="base_link">
    <material>Gazebo/Grey</material>
  </gazebo>
  <gazebo reference="upper_plate_link">
    <material>Gazebo/Grey</material>
  </gazebo>
  <gazebo reference="camera_link">
    <material>Gazebo/DarkGrey</material>
  </gazebo>
  <gazebo reference="left_wheel_link">
    <material>Gazebo/Black</material>
    <mu1>1.0</mu1>
    <mu2>1.0</mu2>
    <kp>1e6</kp>
    <kd>10</kd>
  </gazebo>
  <gazebo reference="right_wheel_link">
    <material>Gazebo/Black</material>
    <mu1>1.0</mu1>
    <mu2>1.0</mu2>
    <kp>1e6</kp>
    <kd>10</kd>
  </gazebo>
  <gazebo reference="caster_wheel_rl_link">
    <material>Gazebo/DarkGrey</material>
    <mu1>0.05</mu1>
    <mu2>0.05</mu2>
    <kp>1e6</kp>
    <kd>10</kd>
  </gazebo>
  <gazebo reference="caster_wheel_rr_link">
    <material>Gazebo/DarkGrey</material>
    <mu1>0.05</mu1>
    <mu2>0.05</mu2>
    <kp>1e6</kp>
    <kd>10</kd>
  </gazebo>
  <gazebo reference="lidar_link">
    <material>Gazebo/Black</material>
    <sensor name="lidar_sensor" type="gpu_lidar">
      <topic>scan</topic>
      <gz_frame_id>lidar_link</gz_frame_id>
      <update_rate>10</update_rate>
      <always_on>true</always_on>
      <visualize>true</visualize>
      <ray>
        <scan>
          <horizontal>
            <samples>360</samples>
            <resolution>1</resolution>
            <min_angle>-3.14159265</min_angle>
            <max_angle> 3.14159265</max_angle>
          </horizontal>
          <vertical>
            <samples>1</samples>
            <resolution>1</resolution>
            <min_angle>0.0</min_angle>
            <max_angle>0.0</max_angle>
          </vertical>
        </scan>
        <range>
          <min>0.12</min>
          <max>12.0</max>
          <resolution>0.01</resolution>
        </range>
      </ray>
    </sensor>
  </gazebo>
  <gazebo reference="camera_link">
    <sensor name="depth_camera" type="rgbd_camera">
      <topic>camera</topic>
      <gz_frame_id>depth_camera_optical_frame</gz_frame_id>
      <update_rate>30</update_rate>
      <always_on>true</always_on>
      <visualize>true</visualize>
      <camera>
        <horizontal_fov>1.5008</horizontal_fov>
        <image>
          <width>640</width>
          <height>480</height>
          <format>R8G8B8</format>
        </image>
        <clip>
          <near>0.1</near>
          <far>10.0</far>
        </clip>
      </camera>
    </sensor>
  </gazebo>
  <gazebo>
    <plugin filename="gz-sim-diff-drive-system" name="gz::sim::systems::DiffDrive">
      <left_joint>left_wheel_joint</left_joint>
      <right_joint>right_wheel_joint</right_joint>
      <wheel_separation>0.395</wheel_separation>
      <wheel_radius>0.085</wheel_radius>
      <max_linear_acceleration>2.0</max_linear_acceleration>
      <max_linear_velocity>1.0</max_linear_velocity>
      <max_angular_velocity>2.0</max_angular_velocity>
      <topic>cmd_vel</topic>
      <odom_topic>odom</odom_topic>
      <tf_topic>tf</tf_topic>
      <frame_id>odom</frame_id>
      <child_frame_id>base_footprint</child_frame_id>
      <odom_publish_frequency>50</odom_publish_frequency>
    </plugin>
    <plugin filename="gz-sim-joint-state-publisher-system" name="gz::sim::systems::JointStatePublisher">
      <topic>joint_states</topic>
      <joint_name>left_wheel_joint</joint_name>
      <joint_name>right_wheel_joint</joint_name>
      <joint_name>caster_yaw_rl_joint</joint_name>
      <joint_name>caster_wheel_rl_joint</joint_name>
      <joint_name>caster_yaw_rr_joint</joint_name>
      <joint_name>caster_wheel_rr_joint</joint_name>
    </plugin>
  </gazebo>
</robot>
